Workbook

Sheet Formulas
A1: Customer Support & Quality Analysis
A4: Formula Guide
A6: Column | B6: Formula | C6: Returns | D6: Reason
A7: Agent Name | B7: =VLOOKUP(...) | C7: Agent name | D7: Connect tickets with agents
A8: Team | B8: =INDEX/MATCH(...) | C8: Support team | D8: Demonstrate alternate lookup
A9: SLA Target | B9: =VLOOKUP(...) | C9: Target hours | D9: Lookup priority target
A10: SLA Status | B10: =IF(...) | C10: Met/Breached | D10: Compare resolution with target
A11: Response Status | B11: =IF(...) | C11: Within/Late | D11: Check first response
A12: Month | B12: =TEXT(...) | C12: 2025-01 | D12: Monthly analysis
A13: CSAT Band | B13: =IF(...) | C13: Good/Average/Poor | D13: Group satisfaction
A14: Duplicate Flag | B14: =COUNTIF(...) | C14: Unique/Duplicate | D14: Quality check

Sheet Agents
A1: agent_id | B1: agent_name | C1: team_lead | D1: team | E1: location
A2: A001 | B2: Ishita Patel | C2: Aman Verma | D2: Email Support | E2: Gurugram
A3: A002 | B3: Gaurav Khan | C3: Aman Verma | D3: Email Support | E3: Noida
A4: A003 | B4: Kabir Verma | C4: Aman Verma | D4: Email Support | E4: Gurugram
A5: A004 | B5: Arjun Agarwal | C5: Aman Verma | D5: Email Support | E5: Bengaluru
A6: A005 | B6: Aditi Verma | C6: Aman Verma | D6: Email Support | E6: Gurugram
A7: A006 | B7: Divya Shah | C7: Kritika Shah | D7: Voice Support | E7: Gurugram
A8: A007 | B8: Kavya Patel | C8: Kritika Shah | D8: Voice Support | E8: Noida
A9: A008 | B9: Ananya Mishra | C9: Kritika Shah | D9: Voice Support | E9: Hyderabad
A10: A009 | B10: Divya Mehta | C10: Kritika Shah | D10: Voice Support | E10: Gurugram
A11: A010 | B11: Ananya Gupta | C11: Kritika Shah | D11: Voice Support | E11: Gurugram
A12: A011 | B12: Shreya Singh | C12: Nitin Gupta | D12: Chat Support | E12: Noida
... A26: A025 | B26: Arjun Nair | C26: Vivek Jain | D26: Seller Support | E26: Noida

Sheet Raw Tickets
A1: ticket_id | B1: created_date | C1: agent_id | D1: channel | E1: issue_type | F1: priority | G1: resolution_hours | H1: first_response_minutes | I1: csat_score | J1: qa_score | K1: status | L1: reopened | M1: escalated
A2: T00001 | B2: 45666 | C2: A001 | D2: Call | E2: Delivery Delay | F2: High | G2: 20.4 | H2: 1 | I2: 2 | J2: 86.1 | K2: Closed | L2: No | M2: No
A3: T00002 | B3: 45999 | C3: A003 | D3: Call | E3: Refund | F3: High | G3: 2.8 | H3: 36 | I3: 4 | J3: 91.2 | K3: Closed | L3: No | M3: No
A4: T00003 | B4: 45734 | C4: A009 | D4: Chat | E4: Delivery Delay | F4: Low | G4: 54.6 | H4: 35 | I4: 5 | J4: 78.2 | K4: Closed | L4: No | M4: No
A5: T00004 | B5: 45899 | C5: A001 | D5: Chat | E5: Refund | F5: Medium | G5: 19.6 | H5: 34 | I5: 4 | J5: 92.2 | K5: Closed | L5: No | M5: No
A6: T00005 | B6: 45662 | C6: A016 | D6: Chat | E6: Order Cancellation | F6: Low | G6: 58 | H6: 23 | I6: 3 | J6: 80 | K6: Closed | L6: No | M6: No
A7: T00006 | B7: 45863 | C7: A011 | D7: Email | E7: Refund | F7: Low | G7: 5.5 | H7: 47 | I7: 3 | J7: 78.5 | K7: Closed | L7: No | M7: No
A8: T00007 | B8: 45801 | C8: A013 | D8: Chat | E8: Account Issue | F8: Critical | G8: 3.5 | H8: 1 | I8: 5 | J8: 72.8 | K8: Closed | L8: No | M8: No
A9: T00008 | B9: 46019 | C9: A007 | D9: Chat | E9: Account Issue | F9: Medium | G9: 22.1 | H9: 51 | I9: 2 | J9: 83.1 | K9: Closed | L9: No | M9: No
A10: T00009 | B10: 45945 | C10: A021 | D10: Email | E10: Delivery Delay | F10: Medium | G10: 8.1 | H10: 27 | I10: 3 | J10: 98.6 | K10: Closed | L10: Yes | M10: No
A11: T00010 | B11: 46005 | C11: A020 | D11: Chat | E11: Delivery Delay | F11: Medium | G11: 0.5 | H11: 6 | I11: 2 | J11: 72 | K11: Closed | L11: Yes | M11: No
A12: T00011 | B12: 45682 | C12: A005 | D12: Call | E12: Order Cancellation | F12: Medium | G12: 26.7 | H12: 20 | I12: 5 | J12: 88.4 | K12: Closed | L12: No | M12: No
A13: T00012 | B13: 45791 | C13: A024 | D13: Email | E13: Account Issue | F13: High | G13: 3.4 | H13: 46 | I13: 5 | J13: 81.6 | K13: Closed | L13: No | M13: No
... A501: T00500 | B501: 45730 | C501: A003 | D501: Call | E501: Payment Failure | F501: Low | G501: 4.8 | H501: 45 | I501: 5 | J501: 87.4 | K501: Closed | L501: No | M501: No

Sheet Ticket Analysis
A1: Ticket_ID | B1: Created_Date | C1: Agent_ID | D1: Channel | E1: Issue_Type | F1: Priority | G1: Resolution_Hours | H1: First_Response_Minutes | I1: CSAT_Score | J1: QA_Score | K1: Status | L1: Reopened | M1: Escalated | N1: Agent_Name | O1: Team | P1: Team_Lead | Q1: Location | R1: SLA_Target_Hours | S1: SLA_Status | T1: Response_Status | U1: Ticket_Month | V1: CSAT_Band | W1: QA_Band | X1: Duplicate_Flag
A2: ='Raw Tickets'!$A$2 -> T00001 | B2: ='Raw Tickets'!$B$2 -> 45666 | C2: ='Raw Tickets'!$C$2 -> A001 | D2: ='Raw Tickets'!$D$2 -> Call | E2: ='Raw Tickets'!$E$2 -> Delivery Delay | F2: ='Raw Tickets'!$F$2 -> High | G2: ='Raw Tickets'!$G$2 -> 20.4 | H2: ='Raw Tickets'!$H$2 -> 1 | I2: ='Raw Tickets'!$I$2 -> 2 | J2: ='Raw Tickets'!$J$2 -> 86.1 | K2: ='Raw Tickets'!$K$2 -> Closed | L2: ='Raw Tickets'!$L$2 -> No | M2: ='Raw Tickets'!$M$2 -> No | N2: =IFERROR(VLOOKUP(C2,Agents!$A$2:$E$26,2,FALSE),"") -> Ishita Patel | O2: =IFERROR(INDEX(Agents!$D$2:$D$26,MATCH(C2,Agents!$A$2:$A$26,0)),"") -> Email Support | P2: =IFERROR(VLOOKUP(C2,Agents!$A$2:$E$26,3,FALSE),"") -> Aman Verma | Q2: =IFERROR(VLOOKUP(C2,Agents!$A$2:$E$26,5,FALSE),"") -> Gurugram | R2: =IFERROR(VLOOKUP(F2,#REF!,2,FALSE),0) -> 0 | S2: =IF(G2<=R2,"Met","Breached") -> Breached | T2: =IF(H2<=30,"Within Target","Late") -> Within Target | U2: =TEXT(B2,"yyyy-mm") -> 2025-01 | V2: =IF(I2>=4,"Good",IF(I2=3,"Average","Poor")) -> Poor | W2: =IF(J2>=85,"Pass","Needs Coaching") -> Pass | X2: =IF(COUNTIF($A$2:$A$501,A2)>1,"Duplicate","Unique") -> Unique
A3: ='Raw Tickets'!$A$3 -> T00002 | B3: ='Raw Tickets'!$B$3 -> 45999 | C3: ='Raw Tickets'!$C$3 -> A003 | D3: ='Raw Tickets'!$D$3 -> Call | E3: ='Raw Tickets'!$E$3 -> Refund | F3: ='Raw Tickets'!$F$3 -> High | G3: ='Raw Tickets'!$G$3 -> 2.8 | H3: ='Raw Tickets'!$H$3 -> 36 | I3: ='Raw Tickets'!$I$3 -> 4 | J3: ='Raw Tickets'!$J$3 -> 91.2 | K3: ='Raw Tickets'!$K$3 -> Closed | L3: ='Raw Tickets'!$L$3 -> No | M3: ='Raw Tickets'!$M$3 -> No | N3: =IFERROR(VLOOKUP(C3,Agents!$A$2:$E$26,2,FALSE),"") -> Kabir Verma | O3: =IFERROR(INDEX(Agents!$D$2:$D$26,MATCH(C3,Agents!$A$2:$A$26,0)),"") -> Email Support | P3: =IFERROR(VLOOKUP(C3,Agents!$A$2:$E$26,3,FALSE),"") -> Aman Verma | Q3: =IFERROR(VLOOKUP(C3,Agents!$A$2:$E$26,5,FALSE),"") -> Gurugram | R3: =IFERROR(VLOOKUP(F3,#REF!,2,FALSE),0) -> 0 | S3: =IF(G3<=R3,"Met","Breached") -> Breached | T3: =IF(H3<=30,"Within Target","Late") -> Late | U3: =TEXT(B3,"yyyy-mm") -> 2025-12 | V3: =IF(I3>=4,"Good",IF(I3=3,"Average","Poor")) -> Good | W3: =IF(J3>=85,"Pass","Needs Coaching") -> Pass | X3: =IF(COUNTIF($A$2:$A$501,A3)>1,"Duplicate","Unique") -> Unique
A4: ='Raw Tickets'!$A$4 -> T00003 | B4: ='Raw Tickets'!$B$4 -> 45734 | C4: ='Raw Tickets'!$C$4 -> A009 | D4: ='Raw Tickets'!$D$4 -> Chat | E4: ='Raw Tickets'!$E$4 -> Delivery Delay | F4: ='Raw Tickets'!$F$4 -> Low | G4: ='Raw Tickets'!$G$4 -> 54.6 | H4: ='Raw Tickets'!$H$4 -> 35 | I4: ='Raw Tickets'!$I$4 -> 5 | J4: ='Raw Tickets'!$J$4 -> 78.2 | K4: ='Raw Tickets'!$K$4 -> Closed | L4: ='Raw Tickets'!$L$4 -> No | M4: ='Raw Tickets'!$M$4 -> No | N4: =IFERROR(VLOOKUP(C4,Agents!$A$2:$E$26,2,FALSE),"") -> Divya Mehta | O4: =IFERROR(INDEX(Agents!$D$2:$D$26,MATCH(C4,Agents!$A$2:$A$26,0)),"") -> Voice Support | P4: =IFERROR(VLOOKUP(C4,Agents!$A$2:$E$26,3,FALSE),"") -> Kritika Shah | Q4: =IFERROR(VLOOKUP(C4,Agents!$A$2:$E$26,5,FALSE),"") -> Gurugram | R4: =IFERROR(VLOOKUP(F4,#REF!,2,FALSE),0) -> 0 | S4: =IF(G4<=R4,"Met","Breached") -> Breached | T4: =IF(H4<=30,"Within Target","Late") -> Late | U4: =TEXT(B4,"yyyy-mm") -> 2025-03 | V4: =IF(I4>=4,"Good",IF(I4=3,"Average","Poor")) -> Good | W4: =IF(J4>=85,"Pass","Needs Coaching") -> Needs Coaching | X4: =IF(COUNTIF($A$2:$A$501,A4)>1,"Duplicate","Unique") -> Unique
A5: ='Raw Tickets'!$A$5 -> T00004 | B5: ='Raw Tickets'!$B$5 -> 45899 | C5: ='Raw Tickets'!$C$5 -> A001 | D5: ='Raw Tickets'!$D$5 -> Chat | E5: ='Raw Tickets'!$E$5 -> Refund | F5: ='Raw Tickets'!$F$5 -> Medium | G5: ='Raw Tickets'!$G$5 -> 19.6 | H5: ='Raw Tickets'!$H$5 -> 34 | I5: ='Raw Tickets'!$I$5 -> 4 | J5: ='Raw Tickets'!$J$5 -> 92.2 | K5: ='Raw Tickets'!$K$5 -> Closed | L5: ='Raw Tickets'!$L$5 -> No | M5: ='Raw Tickets'!$M$5 -> No | N5: =IFERROR(VLOOKUP(C5,Agents!$A$2:$E$26,2,FALSE),"") -> Ishita Patel | O5: =IFERROR(INDEX(Agents!$D$2:$D$26,MATCH(C5,Agents!$A$2:$A$26,0)),"") -> Email Support | P5: =IFERROR(VLOOKUP(C5,Agents!$A$2:$E$26,3,FALSE),"") -> Aman Verma | Q5: =IFERROR(VLOOKUP(C5,Agents!$A$2:$E$26,5,FALSE),"") -> Gurugram | R5: =IFERROR(VLOOKUP(F5,#REF!,2,FALSE),0) -> 0 | S5: =IF(G5<=R5,"Met","Breached") -> Breached | T5: =IF(H5<=30,"Within Target","Late") -> Late | U5: =TEXT(B5,"yyyy-mm") -> 2025-08 | V5: =IF(I5>=4,"Good",IF(I5=3,"Average","Poor")) -> Good | W5: =IF(J5>=85,"Pass","Needs Coaching") -> Pass | X5: =IF(COUNTIF($A$2:$A$501,A5)>1,"Duplicate","Unique") -> Unique
A6: ='Raw Tickets'!$A$6 -> T00005 | B6: ='Raw Tickets'!$B$6 -> 45662 | C6: ='Raw Tickets'!$C$6 -> A016 | D6: ='Raw Tickets'!$D$6 -> Chat | E6: ='Raw Tickets'!$E$6 -> Order Cancellation | F6: ='Raw Tickets'!$F$6 -> Low | G6: ='Raw Tickets'!$G$6 -> 58 | H6: ='Raw Tickets'!$H$6 -> 23 | I6: ='Raw Tickets'!$I$6 -> 3 | J6: ='Raw Tickets'!$J$6 -> 80 | K6: ='Raw Tickets'!$K$6 -> Closed | L6: ='Raw Tickets'!$L$6 -> No | M6: ='Raw Tickets'!$M$6 -> No | N6: =IFERROR(VLOOKUP(C6,Agents!$A$2:$E$26,2,FALSE),"") -> Pooja Bansal | O6: =IFERROR(INDEX(Agents!$D$2:$D$26,MATCH(C6,Agents!$A$2:$A$26,0)),"") -> Escalations | P6: =IFERROR(VLOOKUP(C6,Agents!$A$2:$E$26,3,FALSE),"") -> Pallavi Rao | Q6: =IFERROR(VLOOKUP(C6,Agents!$A$2:$E$26,5,FALSE),"") -> Hyderabad | R6: =IFERROR(VLOOKUP(F6,#REF!,2,FALSE),0) -> 0 | S6: =IF(G6<=R6,"Met","Breached") -> Breached | T6: =IF(H6<=30,"Within Target","Late") -> Within Target | U6: =TEXT(B6,"yyyy-mm") -> 2025-01 | V6: =IF(I6>=4,"Good",IF(I6=3,"Average","Poor")) -> Average | W6: =IF(J6>=85,"Pass","Needs Coaching") -> Needs Coaching | X6: =IF(COUNTIF($A$2:$A$501,A6)>1,"Duplicate","Unique") -> Unique
A7: ='Raw Tickets'!$A$7 -> T00006 | B7: ='Raw Tickets'!$B$7 -> 45863 | C7: ='Raw Tickets'!$C$7 -> A011 | D7: ='Raw Tickets'!$D$7 -> Email | E7: ='Raw Tickets'!$E$7 -> Refund | F7: ='Raw Tickets'!$F$7 -> Low | G7: ='Raw Tickets'!$G$7 -> 5.5 | H7: ='Raw Tickets'!$H$7 -> 47 | I7: ='Raw Tickets'!$I$7 -> 3 | J7: ='Raw Tickets'!$J$7 -> 78.5 | K7: ='Raw Tickets'!$K$7 -> Closed | L7: ='Raw Tickets'!$L$7 -> No | M7: ='Raw Tickets'!$M$7 -> No | N7: =IFERROR(VLOOKUP(C7,Agents!$A$2:$E$26,2,FALSE),"") -> Shreya Singh | O7: =IFERROR(INDEX(Agents!$D$2:$D$26,MATCH(C7,Agents!$A$2:$A$26,0)),"") -> Chat Support | P7: =IFERROR(VLOOKUP(C7,Agents!$A$2:$E$26,3,FALSE),"") -> Nitin Gupta | Q7: =IFERROR(VLOOKUP(C7,Agents!$A$2:$E$26,5,FALSE),"") -> Noida | R7: =IFERROR(VLOOKUP(F7,#REF!,2,FALSE),0) -> 0 | S7: =IF(G7<=R7,"Met","Breached") -> Breached | T7: =IF(H7<=30,"Within Target","Late") -> Late | U7: =TEXT(B7,"yyyy-mm") -> 2025-07 | V7: =IF(I7>=4,"Good",IF(I7=3,"Average","Poor")) -> Average | W7: =IF(J7>=85,"Pass","Needs Coaching") -> Needs Coaching | X7: =IF(COUNTIF($A$2:$A$501,A7)>1,"Duplicate","Unique") -> Unique
A8: ='Raw Tickets'!$A$8 -> T00007 | B8: ='Raw Tickets'!$B$8 -> 45801 | C8: ='Raw Tickets'!$C$8 -> A013 | D8: ='Raw Tickets'!$D$8 -> Chat | E8: ='Raw Tickets'!$E$8 -> Account Issue | F8: ='Raw Tickets'!$F$8 -> Critical | G8: ='Raw Tickets'!$G$8 -> 3.5 | H8: ='Raw Tickets'!$H$8 -> 1 | I8: ='Raw Tickets'!$I$8 -> 5 | J8: ='Raw Tickets'!$J$8 -> 72.8 | K8: ='Raw Tickets'!$K$8 -> Closed | L8: ='Raw Tickets'!$L$8 -> No | M8: ='Raw Tickets'!$M$8 -> No | N8: =IFERROR(VLOOKUP(C8,Agents!$A$2:$E$26,2,FALSE),"") -> Ananya Jain | O8: =IFERROR(INDEX(Agents!$D$2:$D$26,MATCH(C8,Agents!$A$2:$A$26,0)),"") -> Chat Support | P8: =IFERROR(VLOOKUP(C8,Agents!$A$2:$E$26,3,FALSE),"") -> Nitin Gupta | Q8: =IFERROR(VLOOKUP(C8,Agents!$A$2:$E$26,5,FALSE),"") -> Hyderabad | R8: =IFERROR(VLOOKUP(F8,#REF!,2,FALSE),0) -> 0 | S8: =IF(G8<=R8,"Met","Breached") -> Breached | T8: =IF(H8<=30,"Within Target","Late") -> Within Target | U8: =TEXT(B8,"yyyy-mm") -> 2025-05 | V8: =IF(I8>=4,"Good",IF(I8=3,"Average","Poor")) -> Good | W8: =IF(J8>=85,"Pass","Needs Coaching") -> Needs Coaching | X8: =IF(COUNTIF($A$2:$A$501,A8)>1,"Duplicate","Unique") -> Unique
A9: ='Raw Tickets'!$A$9 -> T00008 | B9: ='Raw Tickets'!$B$9 -> 46019 | C9: ='Raw Tickets'!$C$9 -> A007 | D9: ='Raw Tickets'!$D$9 -> Chat | E9: ='Raw Tickets'!$E$9 -> Account Issue | F9: ='Raw Tickets'!$F$9 -> Medium | G9: ='Raw Tickets'!$G$9 -> 22.1 | H9: ='Raw Tickets'!$H$9 -> 51 | I9: ='Raw Tickets'!$I$9 -> 2 | J9: ='Raw Tickets'!$J$9 -> 83.1 | K9: ='Raw Tickets'!$K$9 -> Closed | L9: ='Raw Tickets'!$L$9 -> No | M9: ='Raw Tickets'!$M$9 -> No | N9: =IFERROR(VLOOKUP(C9,Agents!$A$2:$E$26,2,FALSE),"") -> Kavya Patel | O9: =IFERROR(INDEX(Agents!$D$2:$D$26,MATCH(C9,Agents!$A$2:$A$26,0)),"") -> Voice Support | P9: =IFERROR(VLOOKUP(C9,Agents!$A$2:$E$26,3,FALSE),"") -> Kritika Shah | Q9: =IFERROR(VLOOKUP(C9,Agents!$A$2:$E$26,5,FALSE),"") -> Noida | R9: =IFERROR(VLOOKUP(F9,#REF!,2,FALSE),0) -> 0 | S9: =IF(G9<=R9,"Met","Breached") -> Breached | T9: =IF(H9<=30,"Within Target","Late") -> Late | U9: =TEXT(B9,"yyyy-mm") -> 2025-12 | V9: =IF(I9>=4,"Good",IF(I9=3,"Average","Poor")) -> Poor | W9: =IF(J9>=85,"Pass","Needs Coaching") -> Needs Coaching | X9: =IF(COUNTIF($A$2:$A$501,A9)>1,"Duplicate","Unique") -> Unique
A10: ='Raw Tickets'!$A$10 -> T00009 | B10: ='Raw Tickets'!$B$10 -> 45945 | C10: ='Raw Tickets'!$C$10 -> A021 | D10: ='Raw Tickets'!$D$10 -> Email | E10: ='Raw Tickets'!$E$10 -> Delivery Delay | F10: ='Raw Tickets'!$F$10 -> Medium | G10: ='Raw Tickets'!$G$10 -> 8.1 | H10: ='Raw Tickets'!$H$10 -> 27 | I10: ='Raw Tickets'!$I$10 -> 3 | J10: ='Raw Tickets'!$J$10 -> 98.6 | K10: ='Raw Tickets'!$K$10 -> Closed | L10: ='Raw Tickets'!$L$10 -> Yes | M10: ='Raw Tickets'!$M$10 -> No | N10: =IFERROR(VLOOKUP(C10,Agents!$A$2:$E$26,2,FALSE),"") -> Nikhil Bansal | O10: =IFERROR(INDEX(Agents!$D$2:$D$26,MATCH(C10,Agents!$A$2:$A$26,0)),"") -> Seller Support | P10: =IFERROR(VLOOKUP(C10,Agents!$A$2:$E$26,3,FALSE),"") -> Vivek Jain | Q10: =IFERROR(VLOOKUP(C10,Agents!$A$2:$E$26,5,FALSE),"") -> Bengaluru | R10: =IFERROR(VLOOKUP(F10,#REF!,2,FALSE),0) -> 0 | S10: =IF(G10<=R10,"Met","Breached") -> Breached | T10: =IF(H10<=30,"Within Target","Late") -> Within Target | U10: =TEXT(B10,"yyyy-mm") -> 2025-10 | V10: =IF(I10>=4,"Good",IF(I10=3,"Average","Poor")) -> Average | W10: =IF(J10>=85,"Pass","Needs Coaching") -> Pass | X10: =IF(COUNTIF($A$2:$A$501,A10)>1,"Duplicate","Unique") -> Unique
A11: ='Raw Tickets'!$A$11 -> T00010 | B11: ='Raw Tickets'!$B$11 -> 46005 | C11: ='Raw Tickets'!$C$11 -> A020 | D11: ='Raw Tickets'!$D$11 -> Chat | E11: ='Raw Tickets'!$E$11 -> Delivery Delay | F11: ='Raw Tickets'!$F$11 -> Medium | G11: ='Raw Tickets'!$G$11 -> 0.5 | H11: ='Raw Tickets'!$H$11 -> 6 | I11: ='Raw Tickets'!$I$11 -> 2 | J11: ='Raw Tickets'!$J$11 -> 72 | K11: ='Raw Tickets'!$K$11 -> Closed | L11: ='Raw Tickets'!$L$11 -> Yes | M11: ='Raw Tickets'!$M$11 -> No | N11: =IFERROR(VLOOKUP(C11,Agents!$A$2:$E$26,2,FALSE),"") -> Aditi Bansal | O11: =IFERROR(INDEX(Agents!$D$2:$D$26,MATCH(C11,Agents!$A$2:$A$26,0)),"") -> Escalations | P11: =IFERROR(VLOOKUP(C11,Agents!$A$2:$E$26,3,FALSE),"") -> Pallavi Rao | Q11: =IFERROR(VLOOKUP(C11,Agents!$A$2:$E$26,5,FALSE),"") -> Noida | R11: =IFERROR(VLOOKUP(F11,#REF!,2,FALSE),0) -> 0 | S11: =IF(G11<=R11,"Met","Breached") -> Breached | T11: =IF(H11<=30,"Within Target","Late") -> Within Target | U11: =TEXT(B11,"yyyy-mm") -> 2025-12 | V11: =IF(I11>=4,"Good",IF(I11=3,"Average","Poor")) -> Poor | W11: =IF(J11>=85,"Pass","Needs Coaching") -> Needs Coaching | X11: =IF(COUNTIF($A$2:$A$501,A11)>1,"Duplicate","Unique") -> Unique
A12: ='Raw Tickets'!$A$12 -> T00011 | B12: ='Raw Tickets'!$B$12 -> 45682 | C12: ='Raw Tickets'!$C$12 -> A005 | D12: ='Raw Tickets'!$D$12 -> Call | E12: ='Raw Tickets'!$E$12 -> Order Cancellation | F12: ='Raw Tickets'!$F$12 -> Medium | G12: ='Raw Tickets'!$G$12 -> 26.7 | H12: ='Raw Tickets'!$H$12 -> 20 | I12: ='Raw Tickets'!$I$12 -> 5 | J12: ='Raw Tickets'!$J$12 -> 88.4 | K12: ='Raw Tickets'!$K$12 -> Closed | L12: ='Raw Tickets'!$L$12 -> No | M12: ='Raw Tickets'!$M$12 -> No | N12: =IFERROR(VLOOKUP(C12,Agents!$A$2:$E$26,2,FALSE),"") -> Aditi Verma | O12: =IFERROR(INDEX(Agents!$D$2:$D$26,MATCH(C12,Agents!$A$2:$A$26,0)),"") -> Email Support | P12: =IFERROR(VLOOKUP(C12,Agents!$A$2:$E$26,3,FALSE),"") -> Aman Verma | Q12: =IFERROR(VLOOKUP(C12,Agents!$A$2:$E$26,5,FALSE),"") -> Gurugram | R12: =IFERROR(VLOOKUP(F12,#REF!,2,FALSE),0) -> 0 | S12: =IF(G12<=R12,"Met","Breached") -> Breached | T12: =IF(H12<=30,"Within Target","Late") -> Within Target | U12: =TEXT(B12,"yyyy-mm") -> 2025-01 | V12: =IF(I12>=4,"Good",IF(I12=3,"Average","Poor")) -> Good | W12: =IF(J12>=85,"Pass","Needs Coaching") -> Pass | X12: =IF(COUNTIF($A$2:$A$501,A12)>1,"Duplicate","Unique") -> Unique
A13: ='Raw Tickets'!$A$13 -> T00012 | B13: ='Raw Tickets'!$B$13 -> 45791 | C13: ='Raw Tickets'!$C$13 -> A024 | D13: ='Raw Tickets'!$D$13 -> Email | E13: ='Raw Tickets'!$E$13 -> Account Issue | F13: ='Raw Tickets'!$F$13 -> High | G13: ='Raw Tickets'!$G$13 -> 3.4 | H13: ='Raw Tickets'!$H$13 -> 46 | I13: ='Raw Tickets'!$I$13 -> 5 | J13: ='Raw Tickets'!$J$13 -> 81.6 | K13: ='Raw Tickets'!$K$13 -> Closed | L13: ='Raw Tickets'!$L$13 -> No | M13: ='Raw Tickets'!$M$13 -> No | N13: =IFERROR(VLOOKUP(C13,Agents!$A$2:$E$26,2,FALSE),"") -> Rohan Verma | O13: =IFERROR(INDEX(Agents!$D$2:$D$26,MATCH(C13,Agents!$A$2:$A$26,0)),"") -> Seller Support | P13: =IFERROR(VLOOKUP(C13,Agents!$A$2:$E$26,3,FALSE),"") -> Vivek Jain | Q13: =IFERROR(VLOOKUP(C13,Agents!$A$2:$E$26,5,FALSE),"") -> Noida | R13: =IFERROR(VLOOKUP(F13,#REF!,2,FALSE),0) -> 0 | S13: =IF(G13<=R13,"Met","Breached") -> Breached | T13: =IF(H13<=30,"Within Target","Late") -> Late | U13: =TEXT(B13,"yyyy-mm") -> 2025-05 | V13: =IF(I13>=4,"Good",IF(I13=3,"Average","Poor")) -> Good | W13: =IF(J13>=85,"Pass","Needs Coaching") -> Needs Coaching | X13: =IF(COUNTIF($A$2:$A$501,A13)>1,"Duplicate","Unique") -> Unique
A14: ='Raw Tickets'!$A$14 -> T00013 | B14: ='Raw Tickets'!$B$14 -> 45694 | C14: ='Raw Tickets'!$C$14 -> A013 | D14: ='Raw Tickets'!$D$14 -> Chat | E14: ='Raw Tickets'!$E$14 -> Order Cancellation | F14: ='Raw Tickets'!$F$14 -> Low | G14: ='Raw Tickets'!$G$14 -> 12.6 | H14: ='Raw Tickets'!$H$14 -> 41 | I14: ='Raw Tickets'!$I$14 -> 4 | J14: ='Raw Tickets'!$J$14 -> 86.9 | K14: ='Raw Tickets'!$K$14 -> Closed | L14: ='Raw Tickets'!$L$14 -> No | M14: ='Raw Tickets'!$M$14 -> No | N14: =IFERROR(VLOOKUP(C14,Agents!$A$2:$E$26,2,FALSE),"") -> Ananya Jain | O14: =IFERROR(INDEX(Agents!$D$2:$D$26,MATCH(C14,Agents!$A$2:$A$26,0)),"") -> Chat Support | P14: =IFERROR(VLOOKUP(C14,Agents!$A$2:$E$26,3,FALSE),"") -> Nitin Gupta | Q14: =IFERROR(VLOOKUP(C14,Agents!$A$2:$E$26,5,FALSE),"") -> Hyderabad | R14: =IFERROR(VLOOKUP(F14,#REF!,2,FALSE),0) -> 0 | S14: =IF(G14<=R14,"Met","Breached") -> Breached | T14: =IF(H14<=30,"Within Target","Late") -> Late | U14: =TEXT(B14,"yyyy-mm") -> 2025-02 | V14: =IF(I14>=4,"Good",IF(I14=3,"Average","Poor")) -> Good | W14: =IF(J14>=85,"Pass","Needs Coaching") -> Pass | X14: =IF(COUNTIF($A$2:$A$501,A14)>1,"Duplicate","Unique") -> Unique
A15: ='Raw Tickets'!$A$15 -> T00014 | B15: ='Raw Tickets'!$B$15 -> 45943 | C15: ='Raw Tickets'!$C$15 -> A021 | D15: ='Raw Tickets'!$D$15 -> Email | E15: ='Raw Tickets'!$E$15 -> Refund | F15: ='Raw Tickets'!$F$15 -> High | G15: ='Raw Tickets'!$G$15 -> 5.1 | H15: ='Raw Tickets'!$H$15 -> 15 | I15: ='Raw Tickets'!$I$15 -> 5 | J15: ='Raw Tickets'!$J$15 -> 88.1 | K15: ='Raw Tickets'!$K$15 -> Closed | L15: ='Raw Tickets'!$L$15 -> No | M15: ='Raw Tickets'!$M$15 -> No | N15: =IFERROR(VLOOKUP(C15,Agents!$A$2:$E$26,2,FALSE),"") -> Nikhil Bansal | O15: =IFERROR(INDEX(Agents!$D$2:$D$26,MATCH(C15,Agents!$A$2:$A$26,0)),"") -> Seller Support | P15: =IFERROR(VLOOKUP(C15,Agents!$A$2:$E$26,3,FALSE),"") -> Vivek Jain | Q15: =IFERROR(VLOOKUP(C15,Agents!$A$2:$E$26,5,FALSE),"") -> Bengaluru | R15: =IFERROR(VLOOKUP(F15,#REF!,2,FALSE),0) -> 0 | S15: =IF(G15<=R15,"Met","Breached") -> Breached | T15: =IF(H15<=30,"Within Target","Late") -> Within Target | U15: =TEXT(B15,"yyyy-mm") -> 2025-10 | V15: =IF(I15>=4,"Good",IF(I15=3,"Average","Poor")) -> Good | W15: =IF(J15>=85,"Pass","Needs Coaching") -> Pass | X15: =IF(COUNTIF($A$2:$A$501,A15)>1,"Duplicate","Unique") -> Unique
A16: ='Raw Tickets'!$A$16 -> T00015 | B16: ='Raw Tickets'!$B$16 -> 45915 | C16: ='Raw Tickets'!$C$16 -> A015 | D16: ='Raw Tickets'!$D$16 -> Email | E16: ='Raw Tickets'!$E$16 -> Payment Failure | F16: ='Raw Tickets'!$F$16 -> Medium | G16: ='Raw Tickets'!$G$16 -> 21.3 | H16: ='Raw Tickets'!$H$16 -> 26 | I16: ='Raw Tickets'!$I$16 -> 3 | J16: ='Raw Tickets'!$J$16 -> 82.5 | K16: ='Raw Tickets'!$K$16 -> Closed | L16: ='Raw Tickets'!$L$16 -> No | M16: ='Raw Tickets'!$M$16 -> No | N16: =IFERROR(VLOOKUP(C16,Agents!$A$2:$E$26,2,FALSE),"") -> Neha Jain | O16: =IFERROR(INDEX(Agents!$D$2:$D$26,MATCH(C16,Agents!$A$2:$A$26,0)),"") -> Chat Support | P16: =IFERROR(VLOOKUP(C16,Agents!$A$2:$E$26,3,FALSE),"") -> Nitin Gupta | Q16: =IFERROR(VLOOKUP(C16,Agents!$A$2:$E$26,5,FALSE),"") -> Bengaluru | R16: =IFERROR(VLOOKUP(F16,#REF!,2,FALSE),0) -> 0 | S16: =IF(G16<=R16,"Met","Breached") -> Breached | T16: =IF(H16<=30,"Within Target","Late") -> Within Target | U16: =TEXT(B16,"yyyy-mm") -> 2025-09 | V16: =IF(I16>=4,"Good",IF(I16=3,"Average","Poor")) -> Average | W16: =IF(J16>=85,"Pass","Needs Coaching") -> Needs Coaching | X16: =IF(COUNTIF($A$2:$A$501,A16)>1,"Duplicate","Unique") -> Unique
A17: ='Raw Tickets'!$A$17 -> T00016 | B17: ='Raw Tickets'!$B$17 -> 45910 | C17: ='Raw Tickets'!$C$17 -> A010 | D17: ='Raw Tickets'!$D$17 -> Chat | E17: ='Raw Tickets'!$E$17 -> Product Quality | F17: ='Raw Tickets'!$F$17 -> Low | G17: ='Raw Tickets'!$G$17 -> 51.6 | H17: ='Raw Tickets'!$H$17 -> 57 | I17: ='Raw Tickets'!$I$17 -> 5 | J17: ='Raw Tickets'!$J$17 -> 82.8 | K17: ='Raw Tickets'!$K$17 -> Closed | L17: ='Raw Tickets'!$L$17 -> No | M17: ='Raw Tickets'!$M$17 -> No | N17: =IFERROR(VLOOKUP(C17,Agents!$A$2:$E$26,2,FALSE),"") -> Ananya Gupta | O17: =IFERROR(INDEX(Agents!$D$2:$D$26,MATCH(C17,Agents!$A$2:$A$26,0)),"") -> Voice Support | P17: =IFERROR(VLOOKUP(C17,Agents!$A$2:$E$26,3,FALSE),"") -> Kritika Shah | Q17: =IFERROR(VLOOKUP(C17,Agents!$A$2:$E$26,5,FALSE),"") -> Gurugram | R17: =IFERROR(VLOOKUP(F17,#REF!,2,FALSE),0) -> 0 | S17: =IF(G17<=R17,"Met","Breached") -> Breached | T17: =IF(H17<=30,"Within Target","Late") -> Late | U17: =TEXT(B17,"yyyy-mm") -> 2025-09 | V17: =IF(I17>=4,"Good",IF(I17=3,"Average","Poor")) -> Good | W17: =IF(J17>=85,"Pass","Needs Coaching") -> Needs Coaching | X17: =IF(COUNTIF($A$2:$A$501,A17)>1,"Duplicate","Unique") -> Unique
A18: ='Raw Tickets'!$A$18 -> T00017 | B18: ='Raw Tickets'!$B$18 -> 45879 | C18: ='Raw Tickets'!$C$18 -> A013 | D18: ='Raw Tickets'!$D$18 -> Call | E18: ='Raw Tickets'!$E$18 -> Product Quality | F18: ='Raw Tickets'!$F$18 -> Medium | G18: ='Raw Tickets'!$G$18 -> 7.4 | H18: ='Raw Tickets'!$H$18 -> 20 | I18: ='Raw Tickets'!$I$18 -> 5 | J18: ='Raw Tickets'!$J$18 -> 96.3 | K18: ='Raw Tickets'!$K$18 -> Closed | L18: ='Raw Tickets'!$L$18 -> No | M18: ='Raw Tickets'!$M$18 -> No | N18: =IFERROR(VLOOKUP(C18,Agents!$A$2:$E$26,2,FALSE),"") -> Ananya Jain | O18: =IFERROR(INDEX(Agents!$D$2:$D$26,MATCH(C18,Agents!$A$2:$A$26,0)),"") -> Chat Support | P18: =IFERROR(VLOOKUP(C18,Agents!$A$2:$E$26,3,FALSE),"") -> Nitin Gupta | Q18: =IFERROR(VLOOKUP(C18,Agents!$A$2:$E$26,5,FALSE),"") -> Hyderabad | R18: =IFERROR(VLOOKUP(F18,#REF!,2,FALSE),0) -> 0 | S18: =IF(G18<=R18,"Met","Breached") -> Breached | T18: =IF(H18<=30,"Within Target","Late") -> Within Target | U18: =TEXT(B18,"yyyy-mm") -> 2025-08 | V18: =IF(I18>=4,"Good",IF(I18=3,"Average","Poor")) -> Good | W18: =IF(J18>=85,"Pass","Needs Coaching") -> Pass | X18: =IF(COUNTIF($A$2:$A$501,A18)>1,"Duplicate","Unique") -> Unique
A19: ='Raw Tickets'!$A$19 -> T00018 | B19: ='Raw Tickets'!$B$19 -> 45856 | C19: ='Raw Tickets'!$C$19 -> A022 | D19: ='Raw Tickets'!$D$19 -> Chat | E19: ='Raw Tickets'!$E$19 -> Delivery Delay | F19: ='Raw Tickets'!$F$19 -> High | G19: ='Raw Tickets'!$G$19 -> 3 | H19: ='Raw Tickets'!$H$19 -> 1 | I19: ='Raw Tickets'!$I$19 -> 1 | J19: ='Raw Tickets'!$J$19 -> 91.7 | K19: ='Raw Tickets'!$K$19 -> Closed | L19: ='Raw Tickets'!$L$19 -> No | M19: ='Raw Tickets'!$M$19 -> No | N19: =IFERROR(VLOOKUP(C19,Agents!$A$2:$E$26,2,FALSE),"") -> Varun Sharma | O19: =IFERROR(INDEX(Agents!$D$2:$D$26,MATCH(C19,Agents!$A$2:$A$26,0)),"") -> Seller Support | P19: =IFERROR(VLOOKUP(C19,Agents!$A$2:$E$26,3,FALSE),"") -> Vivek Jain | Q19: =IFERROR(VLOOKUP(C19,Agents!$A$2:$E$26,5,FALSE),"") -> Noida | R19: =IFERROR(VLOOKUP(F19,#REF!,2,FALSE),0) -> 0 | S19: =IF(G19<=R19,"Met","Breached") -> Breached | T19: =IF(H19<=30,"Within Target","Late") -> Within Target | U19: =TEXT(B19,"yyyy-mm") -> 2025-07 | V19: =IF(I19>=4,"Good",IF(I19=3,"Average","Poor")) -> Poor | W19: =IF(J19>=85,"Pass","Needs Coaching") -> Pass | X19: =IF(COUNTIF($A$2:$A$501,A19)>1,"Duplicate","Unique") -> Unique
A20: ='Raw Tickets'!$A$20 -> T00019 | B20: ='Raw Tickets'!$B$20 -> 45953 | C20: ='Raw Tickets'!$C$20 -> A005 | D20: ='Raw Tickets'!$D$20 -> Call | E20: ='Raw Tickets'!$E$20 -> Delivery Delay | F20: ='Raw Tickets'!$F$20 -> Low | G20: ='Raw Tickets'!$G$20 -> 11.4 | H20: ='Raw Tickets'!$H$20 -> 80 | I20: ='Raw Tickets'!$I$20 -> 5 | J20: ='Raw Tickets'!$J$20 -> 80 | K20: ='Raw Tickets'!$K$20 -> Closed | L20: ='Raw Tickets'!$L$20 -> No | M20: ='Raw Tickets'!$M$20 -> No | N20: =IFERROR(VLOOKUP(C20,Agents!$A$2:$E$26,2,FALSE),"") -> Aditi Verma | O20: =IFERROR(INDEX(Agents!$D$2:$D$26,MATCH(C20,Agents!$A$2:$A$26,0)),"") -> Email Support | P20: =IFERROR(VLOOKUP(C20,Agents!$A$2:$E$26,3,FALSE),"") -> Aman Verma | Q20: =IFERROR(VLOOKUP(C20,Agents!$A$2:$E$26,5,FALSE),"") -> Gurugram | R20: =IFERROR(VLOOKUP(F20,#REF!,2,FALSE),0) -> 0 | S20: =IF(G20<=R20,"Met","Breached") -> Breached | T20: =IF(H20<=30,"Within Target","Late") -> Late | U20: =TEXT(B20,"yyyy-mm") -> 2025-10 | V20: =IF(I20>=4,"Good",IF(I20=3,"Average","Poor")) -> Good | W20: =IF(J20>=85,"Pass","Needs Coaching") -> Needs Coaching | X20: =IF(COUNTIF($A$2:$A$501,A20)>1,"Duplicate","Unique") -> Unique
A21: ='Raw Tickets'!$A$21 -> T00020 | B21: ='Raw Tickets'!$B$21 -> 45910 | C21: ='Raw Tickets'!$C$21 -> A011 | D21: ='Raw Tickets'!$D$21 -> Email | E21: ='Raw Tickets'!$E$21 -> Order Cancellation | F21: ='Raw Tickets'!$F$21 -> Medium | G21: ='Raw Tickets'!$G$21 -> 7.5 | H21: ='Raw Tickets'!$H$21 -> 14 | I21: ='Raw Tickets'!$I$21 -> 5 | J21: ='Raw Tickets'!$J$21 -> 100 | K21: ='Raw Tickets'!$K$21 -> Closed | L21: ='Raw Tickets'!$L$21 -> No | M21: ='Raw Tickets'!$M$21 -> No | N21: =IFERROR(VLOOKUP(C21,Agents!$A$2:$E$26,2,FALSE),"") -> Shreya Singh | O21: =IFERROR(INDEX(Agents!$D$2:$D$26,MATCH(C21,Agents!$A$2:$A$26,0)),"") -> Chat Support | P21: =IFERROR(VLOOKUP(C21,Agents!$A$2:$E$26,3,FALSE),"") -> Nitin Gupta | Q21: =IFERROR(VLOOKUP(C21,Agents!$A$2:$E$26,5,FALSE),"") -> Noida | R21: =IFERROR(VLOOKUP(F21,#REF!,2,FALSE),0) -> 0 | S21: =IF(G21<=R21,"Met","Breached") -> Breached | T21: =IF(H21<=30,"Within Target","Late") -> Within Target | U21: =TEXT(B21,"yyyy-mm") -> 2025-09 | V21: =IF(I21>=4,"Good",IF(I21=3,"Average","Poor")) -> Good | W21: =IF(J21>=85,"Pass","Needs Coaching") -> Pass | X21: =IF(COUNTIF($A$2:$A$501,A21)>1,"Duplicate","Unique") -> Unique
A22: ='Raw Tickets'!$A$22 -> T00021 | B22: ='Raw Tickets'!$B$22 -> 45670 | C22: ='Raw Tickets'!$C$22 -> A014 | D22: ='Raw Tickets'!$D$22 -> Call | E22: ='Raw Tickets'!$E$22 -> Delivery Delay | F22: ='Raw Tickets'!$F$22 -> Medium | G22: ='Raw Tickets'!$G$22 -> 32 | H22: ='Raw Tickets'!$H$22 -> 53 | I22: ='Raw Tickets'!$I$22 -> 4 | J22: ='Raw Tickets'!$J$22 -> 87.5 | K22: ='Raw Tickets'!$K$22 -> Closed | L22: ='Raw Tickets'!$L$22 -> No | M22: ='Raw Tickets'!$M$22 -> No | N22: =IFERROR(VLOOKUP(C22,Agents!$A$2:$E$26,2,FALSE),"") -> Ananya Jain | O22: =IFERROR(INDEX(Agents!$D$2:$D$26,MATCH(C22,Agents!$A$2:$A$26,0)),"") -> Chat Support | P22: =IFERROR(VLOOKUP(C22,Agents!$A$2:$E$26,3,FALSE),"") -> Nitin Gupta | Q22: =IFERROR(VLOOKUP(C22,Agents!$A$2:$E$26,5,FALSE),"") -> Bengaluru | R22: =IFERROR(VLOOKUP(F22,#REF!,2,FALSE),0) -> 0 | S22: =IF(G22<=R22,"Met","Breached") -> Breached | T22: =IF(H22<=30,"Within Target","Late") -> Late | U22: =TEXT(B22,"yyyy-mm") -> 2025-01 | V22: =IF(I22>=4,"Good",IF(I22=3,"Average","Poor")) -> Good | W22: =IF(J22>=85,"Pass","Needs Coaching") -> Pass | X22: =IF(COUNTIF($A$2:$A$501,A22)>1,"Duplicate","Unique") -> Unique
A23: ='Raw Tickets'!$A$23 -> T00022 | B23: ='Raw Tickets'!$B$23 -> 45673 | C23: ='Raw Tickets'!$C$23 -> A008 | D23: ='Raw Tickets'!$D$23 -> Chat | E23: ='Raw Tickets'!$E$23 -> Order Cancellation | F23: ='Raw Tickets'!$F$23 -> Low | G23: ='Raw Tickets'!$G$23 -> 73.6 | H23: ='Raw Tickets'!$H$23 -> 25 | I23: ='Raw Tickets'!$I$23 -> 4 | J23: ='Raw Tickets'!$J$23 -> 93 | K23: ='Raw Tickets'!$K$23 -> Closed | L23: ='Raw Tickets'!$L$23 -> No | M23: ='Raw Tickets'!$M$23 -> No | N23: =IFERROR(VLOOKUP(C23,Agents!$A$2:$E$26,2,FALSE),"") -> Ananya Mishra | O23: =IFERROR(INDEX(Agents!$D$2:$D$26,MATCH(C23,Agents!$A$2:$A$26,0)),"") -> Voice Support | P23: =IFERROR(VLOOKUP(C23,Agents!$A$2:$E$26,3,FALSE),"") -> Kritika Shah | Q23: =IFERROR(VLOOKUP(C23,Agents!$A$2:$E$26,5,FALSE),"") -> Hyderabad | R23: =IFERROR(VLOOKUP(F23,#REF!,2,FALSE),0) -> 0 | S23: =IF(G23<=R23,"Met","Breached") -> Breached | T23: =IF(H23<=30,"Within Target","Late") -> Within Target | U23: =TEXT(B23,"yyyy-mm") -> 2025-01 | V23: =IF(I23>=4,"Good",IF(I23=3,"Average","Poor")) -> Good | W23: =IF(J23>=85,"Pass","Needs Coaching") -> Pass | X23: =IF(COUNTIF($A$2:$A$501,A23)>1,"Duplicate","Unique") -> Unique
A24: ='Raw Tickets'!$A$24 -> T00023 | B24: ='Raw Tickets'!$B$24 -> 45674 | C24: ='Raw Tickets'!$C$24 -> A024 | D24: ='Raw Tickets'!$D$24 -> Chat | E24: ='Raw Tickets'!$E$24 -> Account Issue | F24: ='Raw Tickets'!$F$24 -> Medium | G24: ='Raw Tickets'!$G$24 -> 26.9 | H24: ='Raw Tickets'!$H$24 -> 1 | I24: ='Raw Tickets'!$I$24 -> 4 | J24: ='Raw Tickets'!$J$24 -> 85 | K24: ='Raw Tickets'!$K$24 -> Closed | L24: ='Raw Tickets'!$L$24 -> No | M24: ='Raw Tickets'!$M$24 -> No | N24: =IFERROR(VLOOKUP(C24,Agents!$A$2:$E$26,2,FALSE),"") -> Rohan Verma | O24: =IFERROR(INDEX(Agents!$D$2:$D$26,MATCH(C24,Agents!$A$2:$A$26,0)),"") -> Seller Support | P24: =IFERROR(VLOOKUP(C24,Agents!$A$2:$E$26,3,FALSE),"") -> Vivek Jain | Q24: =IFERROR(VLOOKUP(C24,Agents!$A$2:$E$26,5,FALSE),"") -> Noida | R24: =IFERROR(VLOOKUP(F24,#REF!,2,FALSE),0) -> 0 | S24: =IF(G24<=R24,"Met","Breached") -> Breached | T24: =IF(H24<=30,"Within Target","Late") -> Within Target | U24: =TEXT(B24,"yyyy-mm") -> 2025-01 | V24: =IF(I24>=4,"Good",IF(I24=3,"Average","Poor")) -> Good | W24: =IF(J24>=85,"Pass","Needs Coaching") -> Pass | X24: =IF(COUNTIF($A$2:$A$501,A24)>1,"Duplicate","Unique") -> Unique
A25: ='Raw Tickets'!$A$25 -> T00024 | B25: ='Raw Tickets'!$B$25 -> 45702 | C25: ='Raw Tickets'!$C$25 -> A024 | D25: ='Raw Tickets'!$D$25 -> Email | E25: ='Raw Tickets'!$E$25 -> Order Cancellation | F25: ='Raw Tickets'!$F$25 -> Medium | G25: ='Raw Tickets'!$G$25 -> 13 | H25: ='Raw Tickets'!$H$25 -> 25 | I25: ='Raw Tickets'!$I$25 -> 5 | J25: ='Raw Tickets'!$J$25 -> 92.5 | K25: ='Raw Tickets'!$K$25 -> Closed | L25: ='Raw Tickets'!$L$25 -> No | M25: ='Raw Tickets'!$M$25 -> No | N25: =IFERROR(VLOOKUP(C25,Agents!$A$2:$E$26,2,FALSE),"") -> Rohan Verma | O25: =IFERROR(INDEX(Agents!$D$2:$D$26,MATCH(C25,Agents!$A$2:$A$26,0)),"") -> Seller Support | P25: =IFERROR(VLOOKUP(C25,Agents!$A$2:$E$26,3,FALSE),"") -> Vivek Jain | Q25: =IFERROR(VLOOKUP(C25,Agents!$A$2:$E$26,5,FALSE),"") -> Noida | R25: =IFERROR(VLOOKUP(F25,#REF!,2,FALSE),0) -> 0 | S25: =IF(G25<=R25,"Met","Breached") -> Breached | T25: =IF(H25<=30,"Within Target","Late") -> Within Target | U25: =TEXT(B25,"yyyy-mm") -> 2025-02 | V25: =IF(I25>=4,"Good",IF(I25=3,"Average","Poor")) -> Good | W25: =IF(J25>=85,"Pass","Needs Coaching") -> Pass | X25: =IF(COUNTIF($A$2:$A$501,A25)>1,"Duplicate","Unique") -> Unique
A26: ='Raw Tickets'!$A$26 -> T00025 | B26: ='Raw Tickets'!$B$26 -> 45868 | C26: ='Raw Tickets'!$C$26 -> A016 | D26: ='Raw Tickets'!$D$26 -> Email | E26: ='Raw Tickets'!$E$26 -> Order Cancellation | F26: ='Raw Tickets'!$F$26 -> Medium | G26: ='Raw Tickets'!$G$26 -> 25.1 | H26: ='Raw Tickets'!$H$26 -> 44 | I26: ='Raw Tickets'!$I$26 -> 5 | J26: ='Raw Tickets'!$J$26 -> 82.3 | K26: ='Raw Tickets'!$K$26 -> Closed | L26: ='Raw Tickets'!$L$26 -> No | M26: ='Raw Tickets'!$M$26 -> No | N26: =IFERROR(VLOOKUP(C26,Agents!$A$2:$E$26,2,FALSE),"") -> Pooja Bansal | O26: =IFERROR(INDEX(Agents!$D$2:$D$26,MATCH(C26,Agents!$A$2:$A$26,0)),"") -> Escalations | P26: =IFERROR(VLOOKUP(C26,Agents!$A$2:$E$26,3,FALSE),"") -> Pallavi Rao | Q26: =IFERROR(VLOOKUP(C26,Agents!$A$2:$E$26,5,FALSE),"") -> Hyderabad | R26: =IFERROR(VLOOKUP(F26,#REF!,2,FALSE),0) -> 0 | S26: =IF(G26<=R26,"Met","Breached") -> Breached | T26: =IF(H26<=30,"Within Target","Late") -> Late | U26: =TEXT(B26,"yyyy-mm") -> 2025-07 | V26: =IF(I26>=4,"Good",IF(I26=3,"Average","Poor")) -> Good | W26: =IF(J26>=85,"Pass","Needs Coaching") -> Needs Coaching | X26: =IF(COUNTIF($A$2:$A$501,A26)>1,"Duplicate","Unique") -> Unique
A27: ='Raw Tickets'!$A$27 -> T00026 | B27: ='Raw Tickets'!$B$27 -> 45819 | C27: ='Raw Tickets'!$C$27 -> A001 | D27: ='Raw Tickets'!$D$27 -> Email | E27: ='Raw Tickets'!$E$27 -> Delivery Delay | F27: ='Raw Tickets'!$F$27 -> Low | G27: ='Raw Tickets'!$G$27 -> 27.3 | H27: ='Raw Tickets'!$H$27 -> 40 | I27: ='Raw Tickets'!$I$27 -> 5 | J27: ='Raw Tickets'!$J$27 -> 83.7 | K27: ='Raw Tickets'!$K$27 -> Closed | L27: ='Raw Tickets'!$L$27 -> No | M27: ='Raw Tickets'!$M$27 -> No | N27: =IFERROR(VLOOKUP(C27,Agents!$A$2:$E$26,2,FALSE),"") -> Ishita Patel | O27: =IFERROR(INDEX(Agents!$D$2:$D$26,MATCH(C27,Agents!$A$2:$A$26,0)),"") -> Email Support | P27: =IFERROR(VLOOKUP(C27,Agents!$A$2:$E$26,3,FALSE),"") -> Aman Verma | Q27: =IFERROR(VLOOKUP(C27,Agents!$A$2:$E$26,5,FALSE),"") -> Gurugram | R27: =IFERROR(VLOOKUP(F27,#REF!,2,FALSE),0) -> 0 | S27: =IF(G27<=R27,"Met","Breached") -> Breached | T27: =IF(H27<=30,"Within Target","Late") -> Late | U27: =TEXT(B27,"yyyy-mm") -> 2025-06 | V27: =IF(I27>=4,"Good",IF(I27=3,"Average","Poor")) -> Good | W27: =IF(J27>=85,"Pass","Needs Coaching") -> Needs Coaching | X27: =IF(COUNTIF($A$2:$A$501,A27)>1,"Duplicate","Unique") -> Unique
A28: ='Raw Tickets'!$A$28 -> T00027 | B28: ='Raw Tickets'!$B$28 -> 45763 | C28: ='Raw Tickets'!$C$28 -> A021 | D28: ='Raw Tickets'!$D$28 -> Email | E28: ='Raw Tickets'!$E$28 -> Product Quality | F28: ='Raw Tickets'!$F$28 -> Medium | G28: ='Raw Tickets'!$G$28 -> 14.5 | H28: ='Raw Tickets'!$H$28 -> 21 | I28: ='Raw Tickets'!$I$28 -> 3 | J28: ='Raw Tickets'!$J$28 -> 75.8 | K28: ='Raw Tickets'!$K$28 -> Open | L28: ='Raw Tickets'!$L$28 -> No | M28: ='Raw Tickets'!$M$28 -> No | N28: =IFERROR(VLOOKUP(C28,Agents!$A$2:$E$26,2,FALSE),"") -> Nikhil Bansal | O28: =IFERROR(INDEX(Agents!$D$2:$D$26,MATCH(C28,Agents!$A$2:$A$26,0)),"") -> Seller Support | P28: =IFERROR(VLOOKUP(C28,Agents!$A$2:$E$26,3,FALSE),"") -> Vivek Jain | Q28: =IFERROR(VLOOKUP(C28,Agents!$A$2:$E$26,5,FALSE),"") -> Bengaluru | R28: =IFERROR(VLOOKUP(F28,#REF!,2,FALSE),0) -> 0 | S28: =IF(G28<=R28,"Met","Breached") -> Breached | T28: =IF(H28<=30,"Within Target","Late") -> Within Target | U28: =TEXT(B28,"yyyy-mm") -> 2025-04 | V28: =IF(I28>=4,"Good",IF(I28=3,"Average","Poor")) -> Average | W28: =IF(J28>=85,"Pass","Needs Coaching") -> Needs Coaching | X28: =IF(COUNTIF($A$2:$A$501,A28)>1,"Duplicate","Unique") -> Unique
A29: ='Raw Tickets'!$A$29 -> T00028 | B29: ='Raw Tickets'!$B$29 -> 45962 | C29: ='Raw Tickets'!$C$29 -> A006 | D29: ='Raw Tickets'!$D$29 -> Call | E29: ='Raw Tickets'!$E$29 -> Payment Failure | F29: ='Raw Tickets'!$F$29 -> Medium | G29: ='Raw Tickets'!$G$29 -> 9.5 | H29: ='Raw Tickets'!$H$29 -> 46 | I29: ='Raw Tickets'!$I$29 -> 5 | J29: ='Raw Tickets'!$J$29 -> 93.3 | K29: ='Raw Tickets'!$K$29 -> Closed | L29: ='Raw Tickets'!$L$29 -> Yes | M29: ='Raw Tickets'!$M$29 -> No | N29: =IFERROR(VLOOKUP(C29,Agents!$A$2:$E$26,2,FALSE),"") -> Divya Shah | O29: =IFERROR(INDEX(Agents!$D$2:$D$26,MATCH(C29,Agents!$A$2:$A$26,0)),"") -> Voice Support | P29: =IFERROR(VLOOKUP(C29,Agents!$A$2:$E$26,3,FALSE),"") -> Kritika Shah | Q29: =IFERROR(VLOOKUP(C29,Agents!$A$2:$E$26,5,FALSE),"") -> Gurugram | R29: =IFERROR(VLOOKUP(F29,#REF!,2,FALSE),0) -> 0 | S29: =IF(G29<=R29,"Met","Breached") -> Breached | T29: =IF(H29<=30,"Within Target","Late") -> Late | U29: =TEXT(B29,"yyyy-mm") -> 2025-11 | V29: =IF(I29>=4,"Good",IF(I29=3,"Average","Poor")) -> Good | W29: =IF(J29>=85,"Pass","Needs Coaching") -> Pass | X29: =IF(COUNTIF($A$2:$A$501,A29)>1,"Duplicate","Unique") -> Unique
A30: ='Raw Tickets'!$A$30 -> T00029 | B30: ='Raw Tickets'!$B$30 -> 45909 | C30: ='Raw Tickets'!$C$30 -> A005 | D30: ='Raw Tickets'!$D$30 -> Email | E30: ='Raw Tickets'!$E$30 -> Product Quality | F30: ='Raw Tickets'!$F$30 -> Low | G30: ='Raw Tickets'!$G$30 -> 30.1 | H30: ='Raw Tickets'!$H$30 -> 40 | I30: ='Raw Tickets'!$I$30 -> 5 | J30: ='Raw Tickets'!$J$30 -> 82.5 | K30: ='Raw Tickets'!$K$30 -> Closed | L30: ='Raw Tickets'!$L$30 -> No | M30: ='Raw Tickets'!$M$30 -> No | N30: =IFERROR(VLOOKUP(C30,Agents!$A$2:$E$26,2,FALSE),"") -> Aditi Verma | O30: =IFERROR(INDEX(Agents!$D$2:$D$26,MATCH(C30,Agents!$A$2:$A$26,0)),"") -> Email Support | P30: =IFERROR(VLOOKUP(C30,Agents!$A$2:$E$26,3,FALSE),"") -> Aman Verma | Q30: =IFERROR(VLOOKUP(C30,Agents!$A$2:$E$26,5,FALSE),"") -> Gurugram | R30: =IFERROR(VLOOKUP(F30,#REF!,2,FALSE),0) -> 0 | S30: =IF(G30<=R30,"Met","Breached") -> Breached | T30: =IF(H30<=30,"Within Target","Late") -> Late | U30: =TEXT(B30,"yyyy-mm") -> 2025-09 | V30: =IF(I30>=4,"Good",IF(I30=3,"Average","Poor")) -> Good | W30: =IF(J30>=85,"Pass","Needs Coaching") -> Needs Coaching | X30: =IF(COUNTIF($A$2:$A$501,A30)>1,"Duplicate","Unique") -> Unique
A31: ='Raw Tickets'!$A$31 -> T00030 | B31: ='Raw Tickets'!$B$31 -> 45751 | C31: ='Raw Tickets'!$C$31 -> A012 | D31: ='Raw Tickets'!$D$31 -> Chat | E31: ='Raw Tickets'!$E$31 -> Payment Failure | F31: ='Raw Tickets'!$F$31 -> Low | G31: ='Raw Tickets'!$G$31 -> 89.6 | H31: ='Raw Tickets'!$H$31 -> 50 | I31: ='Raw Tickets'!$I$31 -> 4 | J31: ='Raw Tickets'!$J$31 -> 94.8 | K31: ='Raw Tickets'!$K$31 -> Open | L31: ='Raw Tickets'!$L$31 -> No | M31: ='Raw Tickets'!$M$31 -> No | N31: =IFERROR(VLOOKUP(C31,Agents!$A$2:$E$26,2,FALSE),"") -> Ankit Khan | O31: =IFERROR(INDEX(Agents!$D$2:$D$26,MATCH(C31,Agents!$A$2:$A$26,0)),"") -> Chat Support | P31: =IFERROR(VLOOKUP(C31,Agents!$A$2:$E$26,3,FALSE),"") -> Nitin Gupta | Q31: =IFERROR(VLOOKUP(C31,Agents!$A$2:$E$26,5,FALSE),"") -> Bengaluru | R31: =IFERROR(VLOOKUP(F31,#REF!,2,FALSE),0) -> 0 | S31: =IF(G31<=R31,"Met","Breached") -> Breached | T31: =IF(H31<=30,"Within Target","Late") -> Late | U31: =TEXT(B31,"yyyy-mm") -> 2025-04 | V31: =IF(I31>=4,"Good",IF(I31=3,"Average","Poor")) -> Good | W31: =IF(J31>=85,"Pass","Needs Coaching") -> Pass | X31: =IF(COUNTIF($A$2:$A$501,A31)>1,"Duplicate","Unique") -> Unique
A32: ='Raw Tickets'!$A$32 -> T00031 | B32: ='Raw Tickets'!$B$32 -> 45665 | C32: ='Raw Tickets'!$C$32 -> A022 | D32: ='Raw Tickets'!$D$32 -> Call | E32: ='Raw Tickets'!$E$32 -> Order Cancellation | F32: ='Raw Tickets'!$F$32 -> Low | G32: ='Raw Tickets'!$G$32 -> 37.5 | H32: ='Raw Tickets'!$H$32 -> 51 | I32: ='Raw Tickets'!$I$32 -> 5 | J32: ='Raw Tickets'!$J$32 -> 85.8 | K32: ='Raw Tickets'!$K$32 -> Closed | L32: ='Raw Tickets'!$L$32 -> No | M32: ='Raw Tickets'!$M$32 -> No | N32: =IFERROR(VLOOKUP(C32,Agents!$A$2:$E$26,2,FALSE),"") -> Varun Sharma | O32: =IFERROR(INDEX(Agents!$D$2:$D$26,MATCH(C32,Agents!$A$2:$A$26,0)),"") -> Seller Support | P32: =IFERROR(VLOOKUP(C32,Agents!$A$2:$E$26,3,FALSE),"") -> Vivek Jain | Q32: =IFERROR(VLOOKUP(C32,Agents!$A$2:$E$26,5,FALSE),"") -> Noida | R32: =IFERROR(VLOOKUP(F32,#REF!,2,FALSE),0) -> 0 | S32: =IF(G32<=R32,"Met","Breached") -> Breached | T32: =IF(H32<=30,"Within Target","Late") -> Late | U32: =TEXT(B32,"yyyy-mm") -> 2025-01 | V32: =IF(I32>=4,"Good",IF(I32=3,"Average","Poor")) -> Good | W32: =IF(J32>=85,"Pass","Needs Coaching") -> Pass | X32: =IF(COUNTIF($A$2:$A$501,A32)>1,"Duplicate","Unique") -> Unique
A33: ='Raw Tickets'!$A$33 -> T00032 | B33: ='Raw Tickets'!$B$33 -> 46001 | C33: ='Raw Tickets'!$C$33 -> A004 | D33: ='Raw Tickets'!$D$33 -> Email | E33: ='Raw Tickets'!$E$33 -> Delivery Delay | F33: ='Raw Tickets'!$F$33 -> Low | G33: ='Raw Tickets'!$G$33 -> 59 | H33: ='Raw Tickets'!$H$33 -> 29 | I33: ='Raw Tickets'!$I$33 -> 5 | J33: ='Raw Tickets'!$J$33 -> 72.4 | K33: ='Raw Tickets'!$K$33 -> Closed | L33: ='Raw Tickets'!$L$33 -> No | M33: ='Raw Tickets'!$M$33 -> No | N33: =IFERROR(VLOOKUP(C33,Agents!$A$2:$E$26,2,FALSE),"") -> Arjun Agarwal | O33: =IFERROR(INDEX(Agents!$D$2:$D$26,MATCH(C33,Agents!$A$2:$A$26,0)),"") -> Email Support | P33: =IFERROR(VLOOKUP(C33,Agents!$A$2:$E$26,3,FALSE),"") -> Aman Verma | Q33: =IFERROR(VLOOKUP(C33,Agents!$A$2:$E$26,5,FALSE),"") -> Bengaluru | R33: =IFERROR(VLOOKUP(F33,#REF!,2,FALSE),0) -> 0 | S33: =IF(G33<=R33,"Met","Breached") -> Breached | T33: =IF(H33<=30,"Within Target","Late") -> Within Target | U33: =TEXT(B33,"yyyy-mm") -> 2025-12 | V33: =IF(I33>=4,"Good",IF(I33=3,"Average","Poor")) -> Good | W33: =IF(J33>=85,"Pass","Needs Coaching") -> Needs Coaching | X33: =IF(COUNTIF($A$2:$A$501,A33)>1,"Duplicate","Unique") -> Unique
A34: ='Raw Tickets'!$A$34 -> T00033 | B34: ='Raw Tickets'!$B$34 -> 45831 | C34: ='Raw Tickets'!$C$34 -> A017 | D34: ='Raw Tickets'!$D$34 -> Chat | E34: ='Raw Tickets'!$E$34 -> Delivery Delay | F34: ='Raw Tickets'!$F$34 -> High | G34: ='Raw Tickets'!$G$34 -> 11.3 | H34: ='Raw Tickets'!$H$34 -> 46 | I34: ='Raw Tickets'!$I$34 -> 5 | J34: ='Raw Tickets'!$J$34 -> 94.3 | K34: ='Raw Tickets'!$K$34 -> Closed | L34: ='Raw Tickets'!$L$34 -> No | M34: ='Raw Tickets'!$M$34 -> Yes | N34: =IFERROR(VLOOKUP(C34,Agents!$A$2:$E$26,2,FALSE),"") -> Varun Mehta | O34: =IFERROR(INDEX(Agents!$D$2:$D$26,MATCH(C34,Agents!$A$2:$A$26,0)),"") -> Escalations | P34: =IFERROR(VLOOKUP(C34,Agents!$A$2:$E$26,3,FALSE),"") -> Pallavi Rao | Q34: =IFERROR(VLOOKUP(C34,Agents!$A$2:$E$26,5,FALSE),"") -> Gurugram | R34: =IFERROR(VLOOKUP(F34,#REF!,2,FALSE),0) -> 0 | S34: =IF(G34<=R34,"Met","Breached") -> Breached | T34: =IF(H34<=30,"Within Target","Late") -> Late | U34: =TEXT(B34,"yyyy-mm") -> 2025-06 | V34: =IF(I34>=4,"Good",IF(I34=3,"Average","Poor")) -> Good | W34: =IF(J34>=85,"Pass","Needs Coaching") -> Pass | X34: =IF(COUNTIF($A$2:$A$501,A34)>1,"Duplicate","Unique") -> Unique
A35: ='Raw Tickets'!$A$35 -> T00034 | B35: ='Raw Tickets'!$B$35 -> 45728 | C35: ='Raw Tickets'!$C$35 -> A003 | D35: ='Raw Tickets'!$D$35 -> Chat | E35: ='Raw Tickets'!$E$35 -> Payment Failure | F35: ='Raw Tickets'!$F$35 -> Low | G35: ='Raw Tickets'!$G$35 -> 24.1 | H35: ='Raw Tickets'!$H$35 -> 49 | I35: ='Raw Tickets'!$I$35 -> 3 | J35: ='Raw Tickets'!$J$35 -> 90.1 | K35: ='Raw Tickets'!$K$35 -> Closed | L35: ='Raw Tickets'!$L$35 -> No | M35: ='Raw Tickets'!$M$35 -> No | N35: =IFERROR(VLOOKUP(C35,Agents!$A$2:$E$26,2,FALSE),"") -> Kabir Verma | O35: =IFERROR(INDEX(Agents!$D$2:$D$26,MATCH(C35,Agents!$A$2:$A$26,0)),"") -> Email Support | P35: =IFERROR(VLOOKUP(C35,Agents!$A$2:$E$26,3,FALSE),"") -> Aman Verma | Q35: =IFERROR(VLOOKUP(C35,Agents!$A$2:$E$26,5,FALSE),"") -> Gurugram | R35: =IFERROR(VLOOKUP(F35,#REF!,2,FALSE),0) -> 0 | S35: =IF(G35<=R35,"Met","Breached") -> Breached | T35: =IF(H35<=30,"Within Target","Late") -> Late | U35: =TEXT(B35,"yyyy-mm") -> 2025-03 | V35: =IF(I35>=4,"Good",IF(I35=3,"Average","Poor")) -> Average | W35: =IF(J35>=85,"Pass","Needs Coaching") -> Pass | X35: =IF(COUNTIF($A$2:$A$501,A35)>1,"Duplicate","Unique") -> Unique
A36: ='Raw Tickets'!$A$36 -> T00035 | B36: ='Raw Tickets'!$B$36 -> 45966 | C36: ='Raw Tickets'!$C$36 -> A014 | D36: ='Raw Tickets'!$D$36 -> Call | E36: ='Raw Tickets'!$E$36 -> Delivery Delay | F36: ='Raw Tickets'!$F$36 -> High | G36: ='Raw Tickets'!$G$36 -> 11.1 | H36: ='Raw Tickets'!$H$36 -> 50 | I36: ='Raw Tickets'!$I$36 -> 5 | J36: ='Raw Tickets'!$J$36 -> 75.9 | K36: ='Raw Tickets'!$K$36 -> Closed | L36: ='Raw Tickets'!$L$36 -> Yes | M36: ='Raw Tickets'!$M$36 -> Yes | N36: =IFERROR(VLOOKUP(C36,Agents!$A$2:$E$26,2,FALSE),"") -> Ananya Jain | O36: =IFERROR(INDEX(Agents!$D$2:$D$26,MATCH(C36,Agents!$A$2:$A$26,0)),"") -> Chat Support | P36: =IFERROR(VLOOKUP(C36,Agents!$A$2:$E$26,3,FALSE),"") -> Nitin Gupta | Q36: =IFERROR(VLOOKUP(C36,Agents!$A$2:$E$26,5,FALSE),"") -> Bengaluru | R36: =IFERROR(VLOOKUP(F36,#REF!,2,FALSE),0) -> 0 | S36: =IF(G36<=R36,"Met","Breached") -> Breached | T36: =IF(H36<=30,"Within Target","Late") -> Late | U36: =TEXT(B36,"yyyy-mm") -> 2025-11 | V36: =IF(I36>=4,"Good",IF(I36=3,"Average","Poor")) -> Good | W36: =IF(J36>=85,"Pass","Needs Coaching") -> Needs Coaching | X36: =IF(COUNTIF($A$2:$A$501,A36)>1,"Duplicate","Unique") -> Unique
A37: ='Raw Tickets'!$A$37 -> T00036 | B37: ='Raw Tickets'!$B$37 -> 45939 | C37: ='Raw Tickets'!$C$37 -> A005 | D37: ='Raw Tickets'!$D$37 -> Call | E37: ='Raw Tickets'!$E$37 -> Payment Failure | F37: ='Raw Tickets'!$F$37 -> Low | G37: ='Raw Tickets'!$G$37 -> 59.6 | H37: ='Raw Tickets'!$H$37 -> 61 | I37: ='Raw Tickets'!$I$37 -> 4 | J37: ='Raw Tickets'!$J$37 -> 75.8 | K37: ='Raw Tickets'!$K$37 -> Closed | L37: ='Raw Tickets'!$L$37 -> No | M37: ='Raw Tickets'!$M$37 -> No | N37: =IFERROR(VLOOKUP(C37,Agents!$A$2:$E$26,2,FALSE),"") -> Aditi Verma | O37: =IFERROR(INDEX(Agents!$D$2:$D$26,MATCH(C37,Agents!$A$2:$A$26,0)),"") -> Email Support | P37: =IFERROR(VLOOKUP(C37,Agents!$A$2:$E$26,3,FALSE),"") -> Aman Verma | Q37: =IFERROR(VLOOKUP(C37,Agents!$A$2:$E$26,5,FALSE),"") -> Gurugram | R37: =IFERROR(VLOOKUP(F37,#REF!,2,FALSE),0) -> 0 | S37: =IF(G37<=R37,"Met","Breached") -> Breached | T37: =IF(H37<=30,"Within Target","Late") -> Late | U37: =TEXT(B37,"yyyy-mm") -> 2025-10 | V37: =IF(I37>=4,"Good",IF(I37=3,"Average","Poor")) -> Good | W37: =IF(J37>=85,"Pass","Needs Coaching") -> Needs Coaching | X37: =IF(COUNTIF($A$2:$A$501,A37)>1,"Duplicate","Unique") -> Unique
A38: ='Raw Tickets'!$A$38 -> T00037 | B38: ='Raw Tickets'!$B$38 -> 45889 | C38: ='Raw Tickets'!$C$38 -> A017 | D38: ='Raw Tickets'!$D$38 -> Call | E38: ='Raw Tickets'!$E$38 -> Order Cancellation | F38: ='Raw Tickets'!$F$38 -> Medium | G38: ='Raw Tickets'!$G$38 -> 30.4 | H38: ='Raw Tickets'!$H$38 -> 25 | I38: ='Raw Tickets'!$I$38 -> 5 | J38: ='Raw Tickets'!$J$38 -> 93.5 | K38: ='Raw Tickets'!$K$38 -> Closed | L38: ='Raw Tickets'!$L$38 -> No | M38: ='Raw Tickets'!$M$38 -> No | N38: =IFERROR(VLOOKUP(C38,Agents!$A$2:$E$26,2,FALSE),"") -> Varun Mehta | O38: =IFERROR(INDEX(Agents!$D$2:$D$26,MATCH(C38,Agents!$A$2:$A$26,0)),"") -> Escalations | P38: =IFERROR(VLOOKUP(C38,Agents!$A$2:$E$26,3,FALSE),"") -> Pallavi Rao | Q38: =IFERROR(VLOOKUP(C38,Agents!$A$2:$E$26,5,FALSE),"") -> Gurugram | R38: =IFERROR(VLOOKUP(F38,#REF!,2,FALSE),0) -> 0 | S38: =IF(G38<=R38,"Met","Breached") -> Breached | T38: =IF(H38<=30,"Within Target","Late") -> Within Target | U38: =TEXT(B38,"yyyy-mm") -> 2025-08 | V38: =IF(I38>=4,"Good",IF(I38=3,"Average","Poor")) -> Good | W38: =IF(J38>=85,"Pass","Needs Coaching") -> Pass | X38: =IF(COUNTIF($A$2:$A$501,A38)>1,"Duplicate","Unique") -> Unique
A39: ='Raw Tickets'!$A$39 -> T00038 | B39: ='Raw Tickets'!$B$39 -> 45890 | C39: ='Raw Tickets'!$C$39 -> A004 | D39: ='Raw Tickets'!$D$39 -> Call | E39: ='Raw Tickets'!$E$39 -> Payment Failure | F39: ='Raw Tickets'!$F$39 -> High | G39: ='Raw Tickets'!$G$39 -> 12.3 | H39: ='Raw Tickets'!$H$39 -> 5 | I39: ='Raw Tickets'!$I$39 -> 4 | J39: ='Raw Tickets'!$J$39 -> 90.8 | K39: ='Raw Tickets'!$K$39 -> Open | L39: ='Raw Tickets'!$L$39 -> No | M39: ='Raw Tickets'!$M$39 -> No | N39: =IFERROR(VLOOKUP(C39,Agents!$A$2:$E$26,2,FALSE),"") -> Arjun Agarwal | O39: =IFERROR(INDEX(Agents!$D$2:$D$26,MATCH(C39,Agents!$A$2:$A$26,0)),"") -> Email Support | P39: =IFERROR(VLOOKUP(C39,Agents!$A$2:$E$26,3,FALSE),"") -> Aman Verma | Q39: =IFERROR(VLOOKUP(C39,Agents!$A$2:$E$26,5,FALSE),"") -> Bengaluru | R39: =IFERROR(VLOOKUP(F39,#REF!,2,FALSE),0) -> 0 | S39: =IF(G39<=R39,"Met","Breached") -> Breached | T39: =IF(H39<=30,"Within Target","Late") -> Within Target | U39: =TEXT(B39,"yyyy-mm") -> 2025-08 | V39: =IF(I39>=4,"Good",IF(I39=3,"Average","Poor")) -> Good | W39: =IF(J39>=85,"Pass","Needs Coaching") -> Pass | X39: =IF(COUNTIF($A$2:$A$501,A39)>1,"Duplicate","Unique") -> Unique
A40: ='Raw Tickets'!$A$40 -> T00039 | B40: ='Raw Tickets'!$B$40 -> 45687 | C40: ='Raw Tickets'!$C$40 -> A001 | D40: ='Raw Tickets'!$D$40 -> Email | E40: ='Raw Tickets'!$E$40 -> Product Quality | F40: ='Raw Tickets'!$F$40 -> Medium | G40: ='Raw Tickets'!$G$40 -> 28.3 | H40: ='Raw Tickets'!$H$40 -> 1 | I40: ='Raw Tickets'!$I$40 -> 5 | J40: ='Raw Tickets'!$J$40 -> 87.5 | K40: ='Raw Tickets'!$K$40 -> Closed | L40: ='Raw Tickets'!$L$40 -> No | M40: ='Raw Tickets'!$M$40 -> No | N40: =IFERROR(VLOOKUP(C40,Agents!$A$2:$E$26,2,FALSE),"") -> Ishita Patel | O40: =IFERROR(INDEX(Agents!$D$2:$D$26,MATCH(C40,Agents!$A$2:$A$26,0)),"") -> Email Support | P40: =IFERROR(VLOOKUP(C40,Agents!$A$2:$E$26,3,FALSE),"") -> Aman Verma | Q40: =IFERROR(VLOOKUP(C40,Agents!$A$2:$E$26,5,FALSE),"") -> Gurugram | R40: =IFERROR(VLOOKUP(F40,#REF!,2,FALSE),0) -> 0 | S40: =IF(G40<=R40,"Met","Breached") -> Breached | T40: =IF(H40<=30,"Within Target","Late") -> Within Target | U40: =TEXT(B40,"yyyy-mm") -> 2025-01 | V40: =IF(I40>=4,"Good",IF(I40=3,"Average","Poor")) -> Good | W40: =IF(J40>=85,"Pass","Needs Coaching") -> Pass | X40: =IF(COUNTIF($A$2:$A$501,A40)>1,"Duplicate","Unique") -> Unique
...

Sheet Summary
A1: Support Performance Summary
A4: Team | B4: Tickets | C4: Avg CSAT | D4: Avg QA | E4: SLA Breaches | G4: Month | H4: Tickets | I4: Avg CSAT | J4: Avg QA
A5: Email Support | B5: =COUNTIF('Ticket Analysis'!$O$2:$O$501,A5) -> 112 | C5: =AVERAGEIF('Ticket Analysis'!$O$2:$O$501,A5,'Ticket Analysis'!$I$2:$I$501) -> 3.8214286 | D5: =AVERAGEIF('Ticket Analysis'!$O$2:$O$501,A5,'Ticket Analysis'!$J$2:$J$501) -> 86.165179 | E5: =COUNTIFS('Ticket Analysis'!$O$2:$O$501,A5,'Ticket Analysis'!$S$2:$S$501,"Breached") -> 112 | G5: 2025-01 | H5: =COUNTIF('Ticket Analysis'!$U$2:$U$501,G5) -> 47 | I5: =AVERAGEIF('Ticket Analysis'!$U$2:$U$501,G5,'Ticket Analysis'!$I$2:$I$501) -> 3.8510638 | J5: =AVERAGEIF('Ticket Analysis'!$U$2:$U$501,G5,'Ticket Analysis'!$J$2:$J$501) -> 85.980851
A6: Voice Support | B6: =COUNTIF('Ticket Analysis'!$O$2:$O$501,A6) -> 103 | C6: =AVERAGEIF('Ticket Analysis'!$O$2:$O$501,A6,'Ticket Analysis'!$I$2:$I$501) -> 3.961165 | D6: =AVERAGEIF('Ticket Analysis'!$O$2:$O$501,A6,'Ticket Analysis'!$J$2:$J$501) -> 85.690291 | E6: =COUNTIFS('Ticket Analysis'!$O$2:$O$501,A6,'Ticket Analysis'!$S$2:$S$501,"Breached") -> 103 | G6: 2025-02 | H6: =COUNTIF('Ticket Analysis'!$U$2:$U$501,G6) -> 39 | I6: =AVERAGEIF('Ticket Analysis'!$U$2:$U$501,G6,'Ticket Analysis'!$I$2:$I$501) -> 3.7948718 | J6: =AVERAGEIF('Ticket Analysis'!$U$2:$U$501,G6,'Ticket Analysis'!$J$2:$J$501) -> 87.048718
A7: Chat Support | B7: =COUNTIF('Ticket Analysis'!$O$2:$O$501,A7) -> 93 | C7: =AVERAGEIF('Ticket Analysis'!$O$2:$O$501,A7,'Ticket Analysis'!$I$2:$I$501) -> 3.8387097 | D7: =AVERAGEIF('Ticket Analysis'!$O$2:$O$501,A7,'Ticket Analysis'!$J$2:$J$501) -> 86.995699 | E7: =COUNTIFS('Ticket Analysis'!$O$2:$O$501,A7,'Ticket Analysis'!$S$2:$S$501,"Breached") -> 93 | G7: 2025-03 | H7: =COUNTIF('Ticket Analysis'!$U$2:$U$501,G7) -> 50 | I7: =AVERAGEIF('Ticket Analysis'!$U$2:$U$501,G7,'Ticket Analysis'!$I$2:$I$501) -> 3.88 | J7: =AVERAGEIF('Ticket Analysis'!$U$2:$U$501,G7,'Ticket Analysis'!$J$2:$J$501) -> 85.252
A8: Escalations | B8: =COUNTIF('Ticket Analysis'!$O$2:$O$501,A8) -> 111 | C8: =AVERAGEIF('Ticket Analysis'!$O$2:$O$501,A8,'Ticket Analysis'!$I$2:$I$501) -> 3.8468468 | D8: =AVERAGEIF('Ticket Analysis'!$O$2:$O$501,A8,'Ticket Analysis'!$J$2:$J$501) -> 86.128829 | E8: =COUNTIFS('Ticket Analysis'!$O$2:$O$501,A8,'Ticket Analysis'!$S$2:$S$501,"Breached") -> 111 | G8: 2025-04 | H8: =COUNTIF('Ticket Analysis'!$U$2:$U$501,G8) -> 37 | I8: =AVERAGEIF('Ticket Analysis'!$U$2:$U$501,G8,'Ticket Analysis'!$I$2:$I$501) -> 3.6216216 | J8: =AVERAGEIF('Ticket Analysis'!$U$2:$U$501,G8,'Ticket Analysis'!$J$2:$J$501) -> 90.145946
A9: Seller Support | B9: =COUNTIF('Ticket Analysis'!$O$2:$O$501,A9) -> 81 | C9: =AVERAGEIF('Ticket Analysis'!$O$2:$O$501,A9,'Ticket Analysis'!$I$2:$I$501) -> 3.9382716 | D9: =AVERAGEIF('Ticket Analysis'!$O$2:$O$501,A9,'Ticket Analysis'!$J$2:$J$501) -> 87.07284 | E9: =COUNTIFS('Ticket Analysis'!$O$2:$O$501,A9,'Ticket Analysis'!$S$2:$S$501,"Breached") -> 81 | G9: 2025-05 | H9: =COUNTIF('Ticket Analysis'!$U$2:$U$501,G9) -> 33 | I9: =AVERAGEIF('Ticket Analysis'!$U$2:$U$501,G9,'Ticket Analysis'!$I$2:$I$501) -> 4.2727273 | J9: =AVERAGEIF('Ticket Analysis'!$U$2:$U$501,G9,'Ticket Analysis'!$J$2:$J$501) -> 83.533333
G10: 2025-06 | H10: =COUNTIF('Ticket Analysis'!$U$2:$U$501,G10) -> 37 | I10: =AVERAGEIF('Ticket Analysis'!$U$2:$U$501,G10,'Ticket Analysis'!$I$2:$I$501) -> 4.1621622 | J10: =AVERAGEIF('Ticket Analysis'!$U$2:$U$501,G10,'Ticket Analysis'!$J$2:$J$501) -> 87.632432
G11: 2025-07 | H11: =COUNTIF('Ticket Analysis'!$U$2:$U$501,G11) -> 54 | I11: =AVERAGEIF('Ticket Analysis'!$U$2:$U$501,G11,'Ticket Analysis'!$I$2:$I$501) -> 3.7407407 | J11: =AVERAGEIF('Ticket Analysis'!$U$2:$U$501,G11,'Ticket Analysis'!$J$2:$J$501) -> 86.37037
G12: 2025-08 | H12: =COUNTIF('Ticket Analysis'!$U$2:$U$501,G12) -> 44 | I12: =AVERAGEIF('Ticket Analysis'!$U$2:$U$501,G12,'Ticket Analysis'!$I$2:$I$501) -> 3.8409091 | J12: =AVERAGEIF('Ticket Analysis'!$U$2:$U$501,G12,'Ticket Analysis'!$J$2:$J$501) -> 85.727273
G13: 2025-09 | H13: =COUNTIF('Ticket Analysis'!$U$2:$U$501,G13) -> 42 | I13: =AVERAGEIF('Ticket Analysis'!$U$2:$U$501,G13,'Ticket Analysis'!$I$2:$I$501) -> 3.9761905 | J13: =AVERAGEIF('Ticket Analysis'!$U$2:$U$501,G13,'Ticket Analysis'!$J$2:$J$501) -> 85.642857
G14: 2025-10 | H14: =COUNTIF('Ticket Analysis'!$U$2:$U$501,G14) -> 42 | I14: =AVERAGEIF('Ticket Analysis'!$U$2:$U$501,G14,'Ticket Analysis'!$I$2:$I$501) -> 4 | J14: =AVERAGEIF('Ticket Analysis'!$U$2:$U$501,G14,'Ticket Analysis'!$J$2:$J$501) -> 87.1
G15: 2025-11 | H15: =COUNTIF('Ticket Analysis'!$U$2:$U$501,G15) -> 39 | I15: =AVERAGEIF('Ticket Analysis'!$U$2:$U$501,G15,'Ticket Analysis'!$I$2:$I$501) -> 3.5897436 | J15: =AVERAGEIF('Ticket Analysis'!$U$2:$U$501,G15,'Ticket Analysis'!$J$2:$J$501) -> 86.128205
G16: 2025-12 | H16: =COUNTIF('Ticket Analysis'!$U$2:$U$501,G16) -> 36 | I16: =AVERAGEIF('Ticket Analysis'!$U$2:$U$501,G16,'Ticket Analysis'!$I$2:$I$501) -> 3.9166667 | J16: =AVERAGEIF('Ticket Analysis'!$U$2:$U$501,G16,'Ticket Analysis'!$J$2:$J$501) -> 86.033333

Sheet Dashboard
A1: CUSTOMER SUPPORT & QUALITY DASHBOARD
A4: Tickets | E4: Average CSAT | I4: Average QA | M4: SLA Breaches
A5: =COUNTA('Ticket Analysis'!$A$2:$A$501) -> 500 | E5: =AVERAGE('Ticket Analysis'!$I$2:$I$501) -> 3.878 | I5: =AVERAGE('Ticket Analysis'!$J$2:$J$501) -> 86.3608 | M5: =COUNTIF('Ticket Analysis'!$S$2:$S$501,"Breached") -> 500
J23: Quality focus Review SLA breaches, coach agents with QA below 85, and monitor reopened or escalated tickets.
